Traceback (most recent call last):
  File "/home/prabhasyadav/anaconda3/lib/python3.8/site-packages/jupyter_cache/executors/utils.py", line 51, in single_nb_execution
    executenb(
  File "/home/prabhasyadav/anaconda3/lib/python3.8/site-packages/nbclient/client.py", line 1087, in execute
    return NotebookClient(nb=nb, resources=resources, km=km, **kwargs).execute()
  File "/home/prabhasyadav/anaconda3/lib/python3.8/site-packages/nbclient/util.py", line 74, in wrapped
    return just_run(coro(*args, **kwargs))
  File "/home/prabhasyadav/anaconda3/lib/python3.8/site-packages/nbclient/util.py", line 53, in just_run
    return loop.run_until_complete(coro)
  File "/home/prabhasyadav/anaconda3/lib/python3.8/asyncio/base_events.py", line 616, in run_until_complete
    return future.result()
  File "/home/prabhasyadav/anaconda3/lib/python3.8/site-packages/nbclient/client.py", line 540, in async_execute
    await self.async_execute_cell(
  File "/home/prabhasyadav/anaconda3/lib/python3.8/site-packages/nbclient/client.py", line 832, in async_execute_cell
    self._check_raise_for_error(cell, exec_reply)
  File "/home/prabhasyadav/anaconda3/lib/python3.8/site-packages/nbclient/client.py", line 740, in _check_raise_for_error
    raise CellExecutionError.from_cell_and_msg(cell, exec_reply['content'])
nbclient.exceptions.CellExecutionError: An error occurred while executing the following cell:
------------------
# Given information
s = 0.19 
Size = [50, 18, 72, 85] # km^2, area
Drawdown = [0.85, 1.09, 1.65, 2.37] # m, equivalent to change in pressure head

# Solution part
Vol_cha = s*np.multiply(Size, Drawdown)*10**6 # m^3, vol change = s*area size * drawdawn



# output printing
y = list(Vol_cha)
y1 = np.transpose([Sub_Area, Size, Drawdown, y]) 
s1 = ips.sheet(columns=4, rows=5, column_headers= Head, row_headers=False, layout=Layout(width='650px', height='250px'))
y1 = ips.cell_range(y1) 
ips.cell(4,3, np.sum(y), background_color="lightgray");s1 

------------------

[0;31m---------------------------------------------------------------------------[0m
[0;31mNameError[0m                                 Traceback (most recent call last)
[0;32m<ipython-input-11-e3b3addd85d2>[0m in [0;36m<module>[0;34m[0m
[1;32m     12[0m [0my[0m [0;34m=[0m [0mlist[0m[0;34m([0m[0mVol_cha[0m[0;34m)[0m[0;34m[0m[0;34m[0m[0m
[1;32m     13[0m [0my1[0m [0;34m=[0m [0mnp[0m[0;34m.[0m[0mtranspose[0m[0;34m([0m[0;34m[[0m[0mSub_Area[0m[0;34m,[0m [0mSize[0m[0;34m,[0m [0mDrawdown[0m[0;34m,[0m [0my[0m[0;34m][0m[0;34m)[0m[0;34m[0m[0;34m[0m[0m
[0;32m---> 14[0;31m [0ms1[0m [0;34m=[0m [0mips[0m[0;34m.[0m[0msheet[0m[0;34m([0m[0mcolumns[0m[0;34m=[0m[0;36m4[0m[0;34m,[0m [0mrows[0m[0;34m=[0m[0;36m5[0m[0;34m,[0m [0mcolumn_headers[0m[0;34m=[0m [0mHead[0m[0;34m,[0m [0mrow_headers[0m[0;34m=[0m[0;32mFalse[0m[0;34m,[0m [0mlayout[0m[0;34m=[0m[0mLayout[0m[0;34m([0m[0mwidth[0m[0;34m=[0m[0;34m'650px'[0m[0;34m,[0m [0mheight[0m[0;34m=[0m[0;34m'250px'[0m[0;34m)[0m[0;34m)[0m[0;34m[0m[0;34m[0m[0m
[0m[1;32m     15[0m [0my1[0m [0;34m=[0m [0mips[0m[0;34m.[0m[0mcell_range[0m[0;34m([0m[0my1[0m[0;34m)[0m[0;34m[0m[0;34m[0m[0m
[1;32m     16[0m [0mips[0m[0;34m.[0m[0mcell[0m[0;34m([0m[0;36m4[0m[0;34m,[0m[0;36m3[0m[0;34m,[0m [0mnp[0m[0;34m.[0m[0msum[0m[0;34m([0m[0my[0m[0;34m)[0m[0;34m,[0m [0mbackground_color[0m[0;34m=[0m[0;34m"lightgray"[0m[0;34m)[0m[0;34m;[0m[0ms1[0m[0;34m[0m[0;34m[0m[0m

[0;31mNameError[0m: name 'Layout' is not defined
NameError: name 'Layout' is not defined

