Traceback (most recent call last):
  File "/home/prabhasyadav/anaconda3/lib/python3.8/site-packages/jupyter_cache/executors/utils.py", line 51, in single_nb_execution
    executenb(
  File "/home/prabhasyadav/anaconda3/lib/python3.8/site-packages/nbclient/client.py", line 1087, in execute
    return NotebookClient(nb=nb, resources=resources, km=km, **kwargs).execute()
  File "/home/prabhasyadav/anaconda3/lib/python3.8/site-packages/nbclient/util.py", line 74, in wrapped
    return just_run(coro(*args, **kwargs))
  File "/home/prabhasyadav/anaconda3/lib/python3.8/site-packages/nbclient/util.py", line 53, in just_run
    return loop.run_until_complete(coro)
  File "/home/prabhasyadav/anaconda3/lib/python3.8/asyncio/base_events.py", line 616, in run_until_complete
    return future.result()
  File "/home/prabhasyadav/anaconda3/lib/python3.8/site-packages/nbclient/client.py", line 540, in async_execute
    await self.async_execute_cell(
  File "/home/prabhasyadav/anaconda3/lib/python3.8/site-packages/nbclient/client.py", line 832, in async_execute_cell
    self._check_raise_for_error(cell, exec_reply)
  File "/home/prabhasyadav/anaconda3/lib/python3.8/site-packages/nbclient/client.py", line 740, in _check_raise_for_error
    raise CellExecutionError.from_cell_and_msg(cell, exec_reply['content'])
nbclient.exceptions.CellExecutionError: An error occurred while executing the following cell:
------------------
# Solution of Problem 11
r5_3 = pn.pane.PNG("images/T03_TP11_a.png", width=400)
r5_4 = pn.pane.LaTeX(r"""
Known relationships are (see Lecture 05, Slides 8-13, 22):
$$
Q = WmK\frac{\Delta H}{L}
$$
$$
K = \frac{Q/W}{m\cdot \Delta H \cdot L}
$$
Weighted arithmetic mean to determine hydraulic conductivity for sand:

$$
K = \frac{1}{m}\sum_{i=1}^n m_i\cdot K_i
$$

where $i$ is different layers
""", width = 500, style={'font-size': '12pt'})
spacer2 = pn.Spacer(width=100)

pn.Row(r5_3, spacer2, r5_4)  
------------------

[0;31m---------------------------------------------------------------------------[0m
[0;31mValueError[0m                                Traceback (most recent call last)
[0;32m<ipython-input-8-46fc3fbedc28>[0m in [0;36m<module>[0;34m[0m
[1;32m      1[0m [0;31m# Solution of Problem 11[0m[0;34m[0m[0;34m[0m[0;34m[0m[0m
[0;32m----> 2[0;31m [0mr5_3[0m [0;34m=[0m [0mpn[0m[0;34m.[0m[0mpane[0m[0;34m.[0m[0mPNG[0m[0;34m([0m[0;34m"images/T03_TP11_a.png"[0m[0;34m,[0m [0mwidth[0m[0;34m=[0m[0;36m400[0m[0;34m)[0m[0;34m[0m[0;34m[0m[0m
[0m[1;32m      3[0m r5_4 = pn.pane.LaTeX(r"""
[1;32m      4[0m [0mKnown[0m [0mrelationships[0m [0mare[0m [0;34m([0m[0msee[0m [0mLecture[0m [0;36m0[0m[0;36m5[0m[0;34m,[0m [0mSlides[0m [0;36m8[0m[0;34m-[0m[0;36m13[0m[0;34m,[0m [0;36m22[0m[0;34m)[0m[0;34m:[0m[0;34m[0m[0;34m[0m[0m
[1;32m      5[0m [0;31m$[0m[0;31m$[0m[0;34m[0m[0;34m[0m[0m

[0;32m~/anaconda3/lib/python3.8/site-packages/panel/pane/base.py[0m in [0;36m__init__[0;34m(self, object, **params)[0m
[1;32m    107[0m         [0mapplies[0m [0;34m=[0m [0mself[0m[0;34m.[0m[0mapplies[0m[0;34m([0m[0mobject[0m[0;34m,[0m [0;34m**[0m[0;34m([0m[0mparams[0m [0;32mif[0m [0mself[0m[0;34m.[0m[0m_applies_kw[0m [0;32melse[0m [0;34m{[0m[0;34m}[0m[0;34m)[0m[0;34m)[0m[0;34m[0m[0;34m[0m[0m
[1;32m    108[0m         [0;32mif[0m [0;34m([0m[0misinstance[0m[0;34m([0m[0mapplies[0m[0;34m,[0m [0mbool[0m[0;34m)[0m [0;32mand[0m [0;32mnot[0m [0mapplies[0m[0;34m)[0m [0;32mand[0m [0mobject[0m [0;32mis[0m [0;32mnot[0m [0;32mNone[0m [0;34m:[0m[0;34m[0m[0;34m[0m[0m
[0;32m--> 109[0;31m             [0mself[0m[0;34m.[0m[0m_type_error[0m[0;34m([0m[0mobject[0m[0;34m)[0m[0;34m[0m[0;34m[0m[0m
[0m[1;32m    110[0m [0;34m[0m[0m
[1;32m    111[0m         [0msuper[0m[0;34m([0m[0mPaneBase[0m[0;34m,[0m [0mself[0m[0;34m)[0m[0;34m.[0m[0m__init__[0m[0;34m([0m[0mobject[0m[0;34m=[0m[0mobject[0m[0;34m,[0m [0;34m**[0m[0mparams[0m[0;34m)[0m[0;34m[0m[0;34m[0m[0m

[0;32m~/anaconda3/lib/python3.8/site-packages/panel/pane/image.py[0m in [0;36m_type_error[0;34m(self, object)[0m
[1;32m     65[0m     [0;32mdef[0m [0m_type_error[0m[0;34m([0m[0mself[0m[0;34m,[0m [0mobject[0m[0;34m)[0m[0;34m:[0m[0;34m[0m[0;34m[0m[0m
[1;32m     66[0m         [0;32mif[0m [0misinstance[0m[0;34m([0m[0mobject[0m[0;34m,[0m [0mstring_types[0m[0;34m)[0m[0;34m:[0m[0;34m[0m[0;34m[0m[0m
[0;32m---> 67[0;31m             raise ValueError("%s pane cannot parse string that is not a filename "
[0m[1;32m     68[0m                              "or URL." % type(self).__name__)
[1;32m     69[0m         [0msuper[0m[0;34m([0m[0mImageBase[0m[0;34m,[0m [0mself[0m[0;34m)[0m[0;34m.[0m[0m_type_error[0m[0;34m([0m[0mobject[0m[0;34m)[0m[0;34m[0m[0;34m[0m[0m

[0;31mValueError[0m: PNG pane cannot parse string that is not a filename or URL.
ValueError: PNG pane cannot parse string that is not a filename or URL.

